{
	"alias": "FEDORA-2019-adc8990386",
	"autokarma": true,
	"autotime": true,
	"bugs": [
		{
			"bug_id": 1781269,
			"parent": true,
			"security": true,
			"title": "CVE-2019-19118 django: privilege escalation in the django admin",
			"bugzilla": {
				"bug_id": "1781269",
				"alias": "CVE-2019-19118",
				"creation_ts": "2019-12-09 16:50:47 +0000",
				"short_desc": "CVE-2019-19118 django: privilege escalation in the django admin",
				"delta_ts": "2021-12-14 18:47:58 +0000",
				"bug_status": "CLOSED",
				"resolution": "WONTFIX",
				"keywords": "Security",
				"priority": "medium",
				"bug_severity": "medium",
				"depends_on": [
					"1781271",
					"1781272",
					"1781270",
					"1781273",
					"1781312",
					"1781361",
					"1807059"
				],
				"blocked": [
					{
						"bug_id": "1781274",
						"error": "NotPermitted"
					}
				],
				"long_desc": [
					{
						"isprivate": "0",
						"commentid": "13440017",
						"comment_count": "0",
						"who": {
							"text": "gsuckevi",
							"name": "Guilherme de Almeida Suckevicz"
						},
						"bug_when": "2019-12-09 16:50:47 +0000",
						"thetext": "Django 2.1 before 2.1.15 and 2.2 before 2.2.8 allows unintended model editing. A Django model admin displaying inline related models, where the user has view-only permissions to a parent model but edit permissions to the inline model, would be presented with an editing UI, allowing POST requests, for updating the inline model. Directly editing the view-only parent model was not possible, but the parent model's save() method was called, triggering potential side effects, and causing pre and post-save signal handlers to be invoked. (To resolve this, the Django admin is adjusted to require edit permissions on the parent model in order for inline models to be editable.)\n\nReference:\nhttps://www.openwall.com/lists/oss-security/2019/12/02/1"
					},
					{
						"isprivate": "0",
						"commentid": "13440028",
						"comment_count": "1",
						"who": {
							"text": "gsuckevi",
							"name": "Guilherme de Almeida Suckevicz"
						},
						"bug_when": "2019-12-09 16:51:12 +0000",
						"thetext": "Created python-django tracking bugs for this issue:\n\nAffects: epel-7 [bug 1781271]\nAffects: epel-8 [bug 1781272]\nAffects: fedora-all [bug 1781270]\nAffects: openstack-rdo [bug 1781273]"
					},
					{
						"isprivate": "0",
						"commentid": "13440048",
						"comment_count": "2",
						"who": {
							"text": "mhroncok",
							"name": "Miro Hrončok"
						},
						"bug_when": "2019-12-09 16:56:10 +0000",
						"thetext": "This does not affect Django 1.x? Because that's what we ship in EPEL 7. And in the Django module. And in the python2-django1.11 package.\n\nThis does not affect Django 3.0?  Because that's what we ship in Fedora 32 (rawhide)."
					},
					{
						"isprivate": "0",
						"commentid": "13440057",
						"comment_count": "3",
						"who": {
							"text": "mhroncok",
							"name": "Miro Hrončok"
						},
						"bug_when": "2019-12-09 16:58:57 +0000",
						"thetext": "3.0 is affected as well, according to https://www.openwall.com/lists/oss-security/2019/12/02/1\n\n1.x is probably unsupported at this point, so we would need to find out ourselves. May I ask to open Bugzillas for https://src.fedoraproject.org/modules/django and https://src.fedoraproject.org/rpms/python2-django1.11 ?"
					},
					{
						"isprivate": "0",
						"commentid": "13440341",
						"comment_count": "4",
						"who": {
							"text": "gsuckevi",
							"name": "Guilherme de Almeida Suckevicz"
						},
						"bug_when": "2019-12-09 18:16:03 +0000",
						"thetext": "Created python2-django1.11 tracking bugs for this issue:\n\nAffects: fedora-all [bug 1781312]"
					},
					{
						"isprivate": "0",
						"commentid": "13440349",
						"comment_count": "5",
						"who": {
							"text": "gsuckevi",
							"name": "Guilherme de Almeida Suckevicz"
						},
						"bug_when": "2019-12-09 18:20:45 +0000",
						"thetext": "(In reply to Miro Hrončok from comment #3)\n> 3.0 is affected as well, according to\n> https://www.openwall.com/lists/oss-security/2019/12/02/1\n> \n> 1.x is probably unsupported at this point, so we would need to find out\n> ourselves. May I ask to open Bugzillas for\n> https://src.fedoraproject.org/modules/django and\n> https://src.fedoraproject.org/rpms/python2-django1.11 ?\n\nPlease use the following trackers:\ndjango: https://bugzilla.redhat.com/show_bug.cgi?id=1781270\npython2-django1.11: https://bugzilla.redhat.com/show_bug.cgi?id=1781312"
					},
					{
						"isprivate": "0",
						"commentid": "13440547",
						"comment_count": "6",
						"who": {
							"text": "mhroncok",
							"name": "Miro Hrončok"
						},
						"bug_when": "2019-12-09 19:19:55 +0000",
						"thetext": "(In reply to Guilherme de Almeida Suckevicz from comment #5)\n> (In reply to Miro Hrončok from comment #3)\n> > 3.0 is affected as well, according to\n> > https://www.openwall.com/lists/oss-security/2019/12/02/1\n> > \n> > 1.x is probably unsupported at this point, so we would need to find out\n> > ourselves. May I ask to open Bugzillas for\n> > https://src.fedoraproject.org/modules/django and\n> > https://src.fedoraproject.org/rpms/python2-django1.11 ?\n> \n> Please use the following trackers:\n> django: https://bugzilla.redhat.com/show_bug.cgi?id=1781270\n\n\nThis is for the nonmodular package. Since the modular one is in completely different version, different upstream and different Fedora maintainer, could you please create a separate bug for the module?"
					},
					{
						"isprivate": "0",
						"commentid": "13440869",
						"comment_count": "7",
						"who": {
							"text": "gsuckevi",
							"name": "Guilherme de Almeida Suckevicz"
						},
						"bug_when": "2019-12-09 21:01:36 +0000",
						"thetext": "Created django:1.6/python-django tracking bugs for this issue:\n\nAffects: fedora-all [bug 1781361]"
					},
					{
						"isprivate": "0",
						"commentid": "13480416",
						"comment_count": "8",
						"who": {
							"text": "rschiron",
							"name": "Riccardo Schirone"
						},
						"bug_when": "2019-12-23 14:51:11 +0000",
						"thetext": "Upstream fix:\nhttps://github.com/django/django/commit/11c5e0609bcc0db93809de2a08e0dc3d70b393e4"
					},
					{
						"isprivate": "0",
						"commentid": "13485618",
						"comment_count": "9",
						"who": {
							"text": "hvyas",
							"name": "Hardik Vyas"
						},
						"bug_when": "2019-12-30 08:35:31 +0000",
						"thetext": "External References:\n\nhttps://www.djangoproject.com/weblog/2019/dec/02/security-releases/"
					},
					{
						"isprivate": "0",
						"commentid": "13485698",
						"comment_count": "10",
						"who": {
							"text": "hvyas",
							"name": "Hardik Vyas"
						},
						"bug_when": "2019-12-30 09:27:20 +0000",
						"thetext": "Statement:\n\nThe version of Django shipped with Red Hat Gluster Storage 3, Red Hat Ceph Storage 2 and Red Hat Ceph Storage 3 is not affected, as edit-permissions are not enabled."
					},
					{
						"isprivate": "0",
						"commentid": "13563988",
						"comment_count": "12",
						"who": {
							"text": "ntait",
							"name": "Nick Tait"
						},
						"bug_when": "2020-01-30 23:39:13 +0000",
						"thetext": "RHOSP 13 and 15 are unaffected as the vulnerable code was not yet introduced."
					},
					{
						"isprivate": "0",
						"commentid": "13564008",
						"comment_count": "13",
						"who": {
							"text": "ntait",
							"name": "Nick Tait"
						},
						"bug_when": "2020-01-30 23:45:54 +0000",
						"thetext": "Mitigation:\n\nThis issue can only be resolved by applying updates.\n\nMitigation for this issue is either not available or the currently available options don't meet the Red Hat Product Security criteria comprising ease of use and deployment, applicability to widespread installation base or stability."
					},
					{
						"isprivate": "0",
						"commentid": "13650224",
						"comment_count": "16",
						"who": {
							"text": "ytale",
							"name": "Yadnyawalk Tale"
						},
						"bug_when": "2020-02-27 07:21:42 +0000",
						"thetext": "Pulp2 owns/carries django-1 and in this case not affected by CVE-2019-19118.\n\nPulp3 chose 2.2 because that is Django's Long-Term-Support version. We do *not* carry/own django-2.2, and pick up whatever \"latest\" is from the repos. Since 2.2.8 has the fix for flaw, and it was released in December, we're already patched here.\n\n# Satellite 6.6.2 -- \n==> rpm -q --whatrequires python-django\npulp-server-2.19.1.1-1.el7sat.noarch\n==> rpm -qa | grep django\npython2-django-1.11.13-1.el7sat.noarch\n\n# Satellite 6.7.0 (snap 13) -- \n==> rpm -q --whatrequires python-django\npulp-server-2.21.0-1.el7sat.noarch\n==> rpm -qa | grep django\npython2-django-1.11.13-1.el7sat.noarch\n\nWe are not affected in Satellite."
					},
					{
						"isprivate": "0",
						"commentid": "13650627",
						"comment_count": "17",
						"who": {
							"text": "prodsec-dev",
							"name": "Product Security DevOps Team"
						},
						"bug_when": "2020-02-27 09:49:32 +0000",
						"thetext": "This bug is now closed. Further updates for individual products will be reflected on the CVE page(s):\n\nhttps://access.redhat.com/security/cve/cve-2019-19118"
					}
				]
			}
		},
		{
			"bug_id": 1781270,
			"security": true,
			"title": "CVE-2019-19118 python-django: django: privilege escalation in the django admin [fedora-all]",
			"bugzilla": {
				"bug_id": "1781270",
				"creation_ts": "2019-12-09 16:50:56 +0000",
				"short_desc": "CVE-2019-19118 python-django: django: privilege escalation in the django admin [fedora-all]",
				"delta_ts": "2019-12-19 01:23:02 +0000",
				"bug_status": "CLOSED",
				"resolution": "ERRATA",
				"keywords": "Security, SecurityTracking",
				"priority": "medium",
				"bug_severity": "medium",
				"blocked": [
					{
						"bug_id": "1781269",
						"alias": "CVE-2019-19118",
						"creation_ts": "2019-12-09 16:50:47 +0000",
						"short_desc": "CVE-2019-19118 django: privilege escalation in the django admin",
						"delta_ts": "2021-12-14 18:47:58 +0000",
						"bug_status": "CLOSED",
						"resolution": "WONTFIX",
						"keywords": "Security",
						"priority": "medium",
						"bug_severity": "medium",
						"depends_on": [
							"1781271",
							"1781272",
							"1781270",
							"1781273",
							"1781312",
							"1781361",
							"1807059"
						],
						"blocked": [
							{
								"bug_id": "1781274",
								"error": "NotPermitted"
							}
						],
						"long_desc": [
							{
								"isprivate": "0",
								"commentid": "13440017",
								"comment_count": "0",
								"who": {
									"text": "gsuckevi",
									"name": "Guilherme de Almeida Suckevicz"
								},
								"bug_when": "2019-12-09 16:50:47 +0000",
								"thetext": "Django 2.1 before 2.1.15 and 2.2 before 2.2.8 allows unintended model editing. A Django model admin displaying inline related models, where the user has view-only permissions to a parent model but edit permissions to the inline model, would be presented with an editing UI, allowing POST requests, for updating the inline model. Directly editing the view-only parent model was not possible, but the parent model's save() method was called, triggering potential side effects, and causing pre and post-save signal handlers to be invoked. (To resolve this, the Django admin is adjusted to require edit permissions on the parent model in order for inline models to be editable.)\n\nReference:\nhttps://www.openwall.com/lists/oss-security/2019/12/02/1"
							},
							{
								"isprivate": "0",
								"commentid": "13440028",
								"comment_count": "1",
								"who": {
									"text": "gsuckevi",
									"name": "Guilherme de Almeida Suckevicz"
								},
								"bug_when": "2019-12-09 16:51:12 +0000",
								"thetext": "Created python-django tracking bugs for this issue:\n\nAffects: epel-7 [bug 1781271]\nAffects: epel-8 [bug 1781272]\nAffects: fedora-all [bug 1781270]\nAffects: openstack-rdo [bug 1781273]"
							},
							{
								"isprivate": "0",
								"commentid": "13440048",
								"comment_count": "2",
								"who": {
									"text": "mhroncok",
									"name": "Miro Hrončok"
								},
								"bug_when": "2019-12-09 16:56:10 +0000",
								"thetext": "This does not affect Django 1.x? Because that's what we ship in EPEL 7. And in the Django module. And in the python2-django1.11 package.\n\nThis does not affect Django 3.0?  Because that's what we ship in Fedora 32 (rawhide)."
							},
							{
								"isprivate": "0",
								"commentid": "13440057",
								"comment_count": "3",
								"who": {
									"text": "mhroncok",
									"name": "Miro Hrončok"
								},
								"bug_when": "2019-12-09 16:58:57 +0000",
								"thetext": "3.0 is affected as well, according to https://www.openwall.com/lists/oss-security/2019/12/02/1\n\n1.x is probably unsupported at this point, so we would need to find out ourselves. May I ask to open Bugzillas for https://src.fedoraproject.org/modules/django and https://src.fedoraproject.org/rpms/python2-django1.11 ?"
							},
							{
								"isprivate": "0",
								"commentid": "13440341",
								"comment_count": "4",
								"who": {
									"text": "gsuckevi",
									"name": "Guilherme de Almeida Suckevicz"
								},
								"bug_when": "2019-12-09 18:16:03 +0000",
								"thetext": "Created python2-django1.11 tracking bugs for this issue:\n\nAffects: fedora-all [bug 1781312]"
							},
							{
								"isprivate": "0",
								"commentid": "13440349",
								"comment_count": "5",
								"who": {
									"text": "gsuckevi",
									"name": "Guilherme de Almeida Suckevicz"
								},
								"bug_when": "2019-12-09 18:20:45 +0000",
								"thetext": "(In reply to Miro Hrončok from comment #3)\n> 3.0 is affected as well, according to\n> https://www.openwall.com/lists/oss-security/2019/12/02/1\n> \n> 1.x is probably unsupported at this point, so we would need to find out\n> ourselves. May I ask to open Bugzillas for\n> https://src.fedoraproject.org/modules/django and\n> https://src.fedoraproject.org/rpms/python2-django1.11 ?\n\nPlease use the following trackers:\ndjango: https://bugzilla.redhat.com/show_bug.cgi?id=1781270\npython2-django1.11: https://bugzilla.redhat.com/show_bug.cgi?id=1781312"
							},
							{
								"isprivate": "0",
								"commentid": "13440547",
								"comment_count": "6",
								"who": {
									"text": "mhroncok",
									"name": "Miro Hrončok"
								},
								"bug_when": "2019-12-09 19:19:55 +0000",
								"thetext": "(In reply to Guilherme de Almeida Suckevicz from comment #5)\n> (In reply to Miro Hrončok from comment #3)\n> > 3.0 is affected as well, according to\n> > https://www.openwall.com/lists/oss-security/2019/12/02/1\n> > \n> > 1.x is probably unsupported at this point, so we would need to find out\n> > ourselves. May I ask to open Bugzillas for\n> > https://src.fedoraproject.org/modules/django and\n> > https://src.fedoraproject.org/rpms/python2-django1.11 ?\n> \n> Please use the following trackers:\n> django: https://bugzilla.redhat.com/show_bug.cgi?id=1781270\n\n\nThis is for the nonmodular package. Since the modular one is in completely different version, different upstream and different Fedora maintainer, could you please create a separate bug for the module?"
							},
							{
								"isprivate": "0",
								"commentid": "13440869",
								"comment_count": "7",
								"who": {
									"text": "gsuckevi",
									"name": "Guilherme de Almeida Suckevicz"
								},
								"bug_when": "2019-12-09 21:01:36 +0000",
								"thetext": "Created django:1.6/python-django tracking bugs for this issue:\n\nAffects: fedora-all [bug 1781361]"
							},
							{
								"isprivate": "0",
								"commentid": "13480416",
								"comment_count": "8",
								"who": {
									"text": "rschiron",
									"name": "Riccardo Schirone"
								},
								"bug_when": "2019-12-23 14:51:11 +0000",
								"thetext": "Upstream fix:\nhttps://github.com/django/django/commit/11c5e0609bcc0db93809de2a08e0dc3d70b393e4"
							},
							{
								"isprivate": "0",
								"commentid": "13485618",
								"comment_count": "9",
								"who": {
									"text": "hvyas",
									"name": "Hardik Vyas"
								},
								"bug_when": "2019-12-30 08:35:31 +0000",
								"thetext": "External References:\n\nhttps://www.djangoproject.com/weblog/2019/dec/02/security-releases/"
							},
							{
								"isprivate": "0",
								"commentid": "13485698",
								"comment_count": "10",
								"who": {
									"text": "hvyas",
									"name": "Hardik Vyas"
								},
								"bug_when": "2019-12-30 09:27:20 +0000",
								"thetext": "Statement:\n\nThe version of Django shipped with Red Hat Gluster Storage 3, Red Hat Ceph Storage 2 and Red Hat Ceph Storage 3 is not affected, as edit-permissions are not enabled."
							},
							{
								"isprivate": "0",
								"commentid": "13563988",
								"comment_count": "12",
								"who": {
									"text": "ntait",
									"name": "Nick Tait"
								},
								"bug_when": "2020-01-30 23:39:13 +0000",
								"thetext": "RHOSP 13 and 15 are unaffected as the vulnerable code was not yet introduced."
							},
							{
								"isprivate": "0",
								"commentid": "13564008",
								"comment_count": "13",
								"who": {
									"text": "ntait",
									"name": "Nick Tait"
								},
								"bug_when": "2020-01-30 23:45:54 +0000",
								"thetext": "Mitigation:\n\nThis issue can only be resolved by applying updates.\n\nMitigation for this issue is either not available or the currently available options don't meet the Red Hat Product Security criteria comprising ease of use and deployment, applicability to widespread installation base or stability."
							},
							{
								"isprivate": "0",
								"commentid": "13650224",
								"comment_count": "16",
								"who": {
									"text": "ytale",
									"name": "Yadnyawalk Tale"
								},
								"bug_when": "2020-02-27 07:21:42 +0000",
								"thetext": "Pulp2 owns/carries django-1 and in this case not affected by CVE-2019-19118.\n\nPulp3 chose 2.2 because that is Django's Long-Term-Support version. We do *not* carry/own django-2.2, and pick up whatever \"latest\" is from the repos. Since 2.2.8 has the fix for flaw, and it was released in December, we're already patched here.\n\n# Satellite 6.6.2 -- \n==> rpm -q --whatrequires python-django\npulp-server-2.19.1.1-1.el7sat.noarch\n==> rpm -qa | grep django\npython2-django-1.11.13-1.el7sat.noarch\n\n# Satellite 6.7.0 (snap 13) -- \n==> rpm -q --whatrequires python-django\npulp-server-2.21.0-1.el7sat.noarch\n==> rpm -qa | grep django\npython2-django-1.11.13-1.el7sat.noarch\n\nWe are not affected in Satellite."
							},
							{
								"isprivate": "0",
								"commentid": "13650627",
								"comment_count": "17",
								"who": {
									"text": "prodsec-dev",
									"name": "Product Security DevOps Team"
								},
								"bug_when": "2020-02-27 09:49:32 +0000",
								"thetext": "This bug is now closed. Further updates for individual products will be reflected on the CVE page(s):\n\nhttps://access.redhat.com/security/cve/cve-2019-19118"
							}
						]
					}
				],
				"long_desc": [
					{
						"isprivate": "0",
						"commentid": "13440020",
						"comment_count": "0",
						"who": {
							"text": "gsuckevi",
							"name": "Guilherme de Almeida Suckevicz"
						},
						"bug_when": "2019-12-09 16:50:56 +0000",
						"thetext": "\nThis is an automatically created tracking bug!  It was created to ensure\nthat one or more security vulnerabilities are fixed in affected versions\nof fedora-all.\n\nFor comments that are specific to the vulnerability please use bugs filed\nagainst the \"Security Response\" product referenced in the \"Blocks\" field.\n\nFor more information see:\nhttp://fedoraproject.org/wiki/Security/TrackingBugs\n\nWhen submitting as an update, use the fedpkg template provided in the next\ncomment(s).  This will include the bug IDs of this tracking bug as well as\nthe relevant top-level CVE bugs.\n\nPlease also mention the CVE IDs being fixed in the RPM changelog and the\nfedpkg commit message.\n\nNOTE: this issue affects multiple supported versions of Fedora. While only\none tracking bug has been filed, please correct all affected versions at\nthe same time.  If you need to fix the versions independent of each other,\nyou may clone this bug as appropriate."
					},
					{
						"isprivate": "0",
						"commentid": "13440021",
						"comment_count": "1",
						"who": {
							"text": "gsuckevi",
							"name": "Guilherme de Almeida Suckevicz"
						},
						"bug_when": "2019-12-09 16:50:58 +0000",
						"thetext": "Use the following template to for the 'fedpkg update' request to submit an\nupdate for this issue as it contains the top-level parent bug(s) as well as\nthis tracking bug.  This will ensure that all associated bugs get updated\nwhen new packages are pushed to stable.\n\n=====\n\n# bugfix, security, enhancement, newpackage (required)\ntype=security\n\n# low, medium, high, urgent (required)\nseverity=medium\n\n# testing, stable\nrequest=testing\n\n# Bug numbers: 1234,9876\nbugs=1781269,1781270\n\n# Description of your update\nnotes=Security fix for [PUT CVEs HERE]\n\n# Enable request automation based on the stable/unstable karma thresholds\nautokarma=True\nstable_karma=3\nunstable_karma=-3\n\n# Automatically close bugs when this marked as stable\nclose_bugs=True\n\n# Suggest that users restart after update\nsuggest_reboot=False\n\n======\n\nAdditionally, you may opt to use the bodhi web interface to submit updates:\n\nhttps://bodhi.fedoraproject.org/updates/new"
					},
					{
						"isprivate": "0",
						"commentid": "13440366",
						"comment_count": "2",
						"who": {
							"text": "mrunge",
							"name": "Matthias Runge"
						},
						"bug_when": "2019-12-09 18:25:18 +0000",
						"thetext": "From upstream project: https://www.djangoproject.com/weblog/2019/dec/02/security-releases/\n\n3.0, 2.2, and 2.1 are affected\n\nAccording to https://www.djangoproject.com/download/#supported-versions\n1.11 still should receive fixes."
					},
					{
						"isprivate": "0",
						"commentid": "13442982",
						"comment_count": "3",
						"who": {
							"text": "updates",
							"name": "Fedora Update System"
						},
						"bug_when": "2019-12-10 10:58:03 +0000",
						"thetext": "FEDORA-2019-adc8990386 has been submitted as an update to Fedora 31. https://bodhi.fedoraproject.org/updates/FEDORA-2019-adc8990386"
					},
					{
						"isprivate": "0",
						"commentid": "13445990",
						"comment_count": "4",
						"who": {
							"text": "updates",
							"name": "Fedora Update System"
						},
						"bug_when": "2019-12-11 01:41:44 +0000",
						"thetext": "python-django-2.2.8-1.fc31 has been pushed to the Fedora 31 testing repository. If problems still persist, please make note of it in this bug report.\nSee https://fedoraproject.org/wiki/QA:Updates_Testing for\ninstructions on how to install test updates.\nYou can provide feedback for this update here: https://bodhi.fedoraproject.org/updates/FEDORA-2019-adc8990386"
					},
					{
						"isprivate": "0",
						"commentid": "13472354",
						"comment_count": "5",
						"who": {
							"text": "updates",
							"name": "Fedora Update System"
						},
						"bug_when": "2019-12-19 01:23:02 +0000",
						"thetext": "python-django-2.2.8-1.fc31 has been pushed to the Fedora 31 stable repository. If problems still persist, please make note of it in this bug report."
					}
				]
			}
		}
	],
	"builds": [
		{
			"epoch": 0,
			"nvr": "python-django-2.2.8-1.fc31",
			"release_id": 33,
			"signed": true,
			"type": "rpm",
			"package": {
				"noarch": [
					{
						"name": "python3-django-doc",
						"version": "2.2.8",
						"release": "1.fc31",
						"arch": "noarch"
					},
					{
						"name": "python-django-bash-completion",
						"version": "2.2.8",
						"release": "1.fc31",
						"arch": "noarch"
					},
					{
						"name": "python3-django",
						"version": "2.2.8",
						"release": "1.fc31",
						"arch": "noarch"
					}
				],
				"src": [
					{
						"name": "python-django",
						"version": "2.2.8",
						"release": "1.fc31",
						"arch": "src"
					}
				]
			}
		}
	],
	"close_bugs": true,
	"comments": [
		{
			"id": 1163980,
			"text": "This update has been submitted for testing by mrunge. ",
			"timestamp": "2019-12-10 10:57:59",
			"update_id": 173623,
			"user": {
				"avatar": "https://apps.fedoraproject.org/img/icons/bodhi-24.png",
				"id": 91,
				"name": "bodhi",
				"openid": "bodhi.id.fedoraproject.org"
			},
			"user_id": 91
		},
		{
			"id": 1163981,
			"text": "This update's test gating status has been changed to 'waiting'.",
			"timestamp": "2019-12-10 10:58:00",
			"update_id": 173623,
			"user": {
				"avatar": "https://apps.fedoraproject.org/img/icons/bodhi-24.png",
				"id": 91,
				"name": "bodhi",
				"openid": "bodhi.id.fedoraproject.org"
			},
			"user_id": 91
		},
		{
			"id": 1163982,
			"text": "This update's test gating status has been changed to 'ignored'.",
			"timestamp": "2019-12-10 10:58:04",
			"update_id": 173623,
			"user": {
				"avatar": "https://apps.fedoraproject.org/img/icons/bodhi-24.png",
				"id": 91,
				"name": "bodhi",
				"openid": "bodhi.id.fedoraproject.org"
			},
			"user_id": 91
		},
		{
			"id": 1164775,
			"text": "This update has been pushed to testing.",
			"timestamp": "2019-12-11 01:42:08",
			"update_id": 173623,
			"user": {
				"avatar": "https://apps.fedoraproject.org/img/icons/bodhi-24.png",
				"id": 91,
				"name": "bodhi",
				"openid": "bodhi.id.fedoraproject.org"
			},
			"user_id": 91
		},
		{
			"id": 1172446,
			"text": "This update can be pushed to stable now if the maintainer wishes",
			"timestamp": "2019-12-18 01:42:26",
			"update_id": 173623,
			"user": {
				"avatar": "https://apps.fedoraproject.org/img/icons/bodhi-24.png",
				"id": 91,
				"name": "bodhi",
				"openid": "bodhi.id.fedoraproject.org"
			},
			"user_id": 91
		},
		{
			"id": 1172447,
			"text": "This update has been submitted for stable by bodhi. ",
			"timestamp": "2019-12-18 01:42:27",
			"update_id": 173623,
			"user": {
				"avatar": "https://apps.fedoraproject.org/img/icons/bodhi-24.png",
				"id": 91,
				"name": "bodhi",
				"openid": "bodhi.id.fedoraproject.org"
			},
			"user_id": 91
		},
		{
			"id": 1173306,
			"text": "This update has been pushed to stable.",
			"timestamp": "2019-12-19 01:23:29",
			"update_id": 173623,
			"user": {
				"avatar": "https://apps.fedoraproject.org/img/icons/bodhi-24.png",
				"id": 91,
				"name": "bodhi",
				"openid": "bodhi.id.fedoraproject.org"
			},
			"user_id": 91
		}
	],
	"content_type": "rpm",
	"date_pushed": "2019-12-19 01:22:32",
	"date_stable": "2019-12-19 01:22:32",
	"date_submitted": "2019-12-10 10:57:59",
	"date_testing": "2019-12-11 01:41:06",
	"display_name": "CVE-2019-19118",
	"meets_testing_requirements": true,
	"notes": "bugfix release for CVE-2019-19118",
	"pushed": true,
	"release": {
		"branch": "f31",
		"candidate_tag": "f31-updates-candidate",
		"composed_by_bodhi": true,
		"create_automatic_updates": false,
		"dist_tag": "f31",
		"id_prefix": "FEDORA",
		"long_name": "Fedora 31",
		"mail_template": "fedora_errata_template",
		"name": "F31",
		"override_tag": "f31-override",
		"package_manager": "dnf",
		"pending_signing_tag": "f31-signing-pending",
		"pending_stable_tag": "f31-updates-pending",
		"pending_testing_tag": "f31-updates-testing-pending",
		"stable_tag": "f31-updates",
		"state": "archived",
		"testing_repository": "updates-testing",
		"testing_tag": "f31-updates-testing",
		"version": "31"
	},
	"require_bugs": true,
	"require_testcases": true,
	"requirements": "",
	"severity": "medium",
	"stable_days": 7,
	"stable_karma": 3,
	"status": "stable",
	"suggest": "unspecified",
	"test_gating_status": "ignored",
	"title": "python-django-2.2.8-1.fc31",
	"type": "security",
	"url": "https://bodhi.fedoraproject.org/updates/FEDORA-2019-adc8990386",
	"unstable_karma": -3,
	"updateid": "FEDORA-2019-adc8990386",
	"user": {
		"avatar": "https://seccdn.libravatar.org/avatar/c626775cb5584b1a49ea4a5cabb248e54e49c09185ebbf4fbce72265255956f0?s=24&d=retro",
		"email": "mrunge@redhat.com",
		"groups": [
			{
				"name": "proventesters"
			},
			{
				"name": "provenpackager"
			},
			{
				"name": "packager"
			},
			{
				"name": "python-sig"
			},
			{
				"name": "centosproject-email-aliases"
			},
			{
				"name": "gitovirt"
			},
			{
				"name": "sig-cloud"
			},
			{
				"name": "ambassadors"
			},
			{
				"name": "gitnodejs-packaging"
			},
			{
				"name": "signed_fpca"
			},
			{
				"name": "python-packagers-sig"
			},
			{
				"name": "sig-extras"
			},
			{
				"name": "fedora-contributor"
			},
			{
				"name": "fedorabugs"
			},
			{
				"name": "sig-opstools"
			},
			{
				"name": "ipausers"
			},
			{
				"name": "sig-messaging"
			},
			{
				"name": "openstack-sig"
			}
		],
		"id": 189,
		"name": "mrunge",
		"openid": "mrunge.id.fedoraproject.org"
	},
	"version_hash": "a8a0ccf066a20873bb915d81bc05e685cfb76b1f"
}
